<?xml version="1.0" encoding="utf-8"?>
<!-- This URDF was automatically created by SolidWorks to URDF Exporter! Originally created by Stephen Brawner (brawner@gmail.com) 
     Commit Version: 1.6.0-4-g7f85cfe  Build Version: 1.6.7995.38578
     For more information, please see http://wiki.ros.org/sw_urdf_exporter -->
<robot
  name="Wholebody_URDF_1125">
  <link
    name="Pelvis">
    <inertial>
      <origin
        xyz="-0.018793 0.000052 0.034756"
        rpy="0 0 0" />
      <mass
        value="6.636796" />
      <inertia
        ixx="0.073763"
        ixy="0.000024"
        ixz="0.001899"
        iyy="0.022641"
        iyz="-0.000003"
        izz="0.087990" />
    </inertial>
    <visual>
      <origin
        xyz="0 0 0"
        rpy="0 0 0" />
      <geometry>
        <mesh
          filename="meshes/Pelvis.STL" />
      </geometry>
      <material
        name="">
        <color
          rgba="0.79216 0.81961 0.93333 1" />
      </material>
    </visual>
    <collision>
      <origin
        xyz="0 0 0"
        rpy="0 0 0" />
      <geometry>
        <mesh
          filename="meshes/Pelvis.STL" />
      </geometry>
    </collision>
  </link>
  <link
    name="Torso">
    <inertial>
      <origin
        xyz="-0.015777 -0.000523 0.232555"
        rpy="0 0 0" />
      <mass
        value="13.423049" />
      <inertia
        ixx="0.226837"
        ixy="0.000171"
        ixz="-0.004416"
        iyy="0.165371"
        iyz="-0.000024"
        izz="0.098576" />
    </inertial>
    <visual>
      <origin
        xyz="0 0 0"
        rpy="0 0 0" />
      <geometry>
        <mesh
          filename="meshes/Torso.STL" />
      </geometry>
      <material
        name="">
        <color
          rgba="0.792156862745098 0.819607843137255 0.933333333333333 1" />
      </material>
    </visual>
    <collision>
      <origin
        xyz="0 0 0"
        rpy="0 0 0" />
      <geometry>
        <mesh
          filename="meshes/Torso.STL" />
      </geometry>
    </collision>
  </link>
  <joint
    name="Waist_joint"
    type="revolute">
    <origin
      xyz="0 0 0.0825"
      rpy="0 0 0" />
    <parent
      link="Pelvis" />
    <child
      link="Torso" />
    <axis
      xyz="0 0 1" />
    <limit
      lower="-1.57"
      upper="1.57"
      effort="100"
      velocity="16" />
  </joint>
  <link
    name="L_shoulder_pitch">
    <inertial>
      <origin
        xyz="0.002264 0.049276 0"
        rpy="0 0 0" />
      <mass
        value="0.4695" />
      <inertia
        ixx="0.000899"
        ixy="-6.5E-05"
        ixz="0"
        iyy="0.000951"
        iyz="0"
        izz="0.001364" />
    </inertial>
    <visual>
      <origin
        xyz="0 0 0"
        rpy="0 0 0" />
      <geometry>
        <mesh
          filename="meshes/L_shoulder_pitch.STL" />
      </geometry>
      <material
        name="">
        <color
          rgba="0.792156862745098 0.819607843137255 0.933333333333333 1" />
      </material>
    </visual>
    <collision>
      <origin
        xyz="0 0 0"
        rpy="0 0 0" />
      <geometry>
        <mesh
          filename="meshes/L_shoulder_pitch.STL" />
      </geometry>
    </collision>
  </link>
  <joint
    name="L_shoulder_pitch_joint"
    type="revolute">
    <origin
      xyz="0 0.16 0.36424"
      rpy="0.34907 0 0" />
    <parent
      link="Torso" />
    <child
      link="L_shoulder_pitch" />
    <axis
      xyz="0 1 0" />
    <limit
      lower="-2.09"
      upper="2.09"
      effort="40"
      velocity="18" />
  </joint>
  <link
    name="L_shoulder_roll">
    <inertial>
      <origin
        xyz="0.000605 6.8E-05 -0.08074"
        rpy="0 0 0" />
      <mass
        value="2.05" />
      <inertia
        ixx="0.020258"
        ixy="-5E-06"
        ixz="-0.000316"
        iyy="0.020052"
        iyz="4.5E-05"
        izz="0.002351" />
    </inertial>
    <visual>
      <origin
        xyz="0 0 0"
        rpy="0 0 0" />
      <geometry>
        <mesh
          filename="meshes/L_shoulder_roll.STL" />
      </geometry>
      <material
        name="">
        <color
          rgba="0.792156862745098 0.819607843137255 0.933333333333333 1" />
      </material>
    </visual>
    <collision>
      <origin
        xyz="0 0 0"
        rpy="0 0 0" />
      <geometry>
        <mesh
          filename="meshes/L_shoulder_roll.STL" />
      </geometry>
    </collision>
  </link>
  <joint
    name="L_shoulder_roll_joint"
    type="revolute">
    <origin
      xyz="0 0.082 0"
      rpy="1.2217304764 0 0" />
    <parent
      link="L_shoulder_pitch" />
    <child
      link="L_shoulder_roll" />
    <axis
      xyz="1 0 0" />
    <limit
      lower="-1.65"
      upper="1.92"
      effort="40"
      velocity="18" />
  </joint>
  <link
    name="L_shoulder_yaw">
    <inertial>
      <origin
        xyz="4.9E-05 0.002116 -0.045474"
        rpy="0 0 0" />
      <mass
        value="0.602" />
      <inertia
        ixx="0.000595"
        ixy="0"
        ixz="0"
        iyy="0.000485"
        iyz="3E-06"
        izz="0.000471" />
    </inertial>
    <visual>
      <origin
        xyz="0 0 0"
        rpy="0 0 0" />
      <geometry>
        <mesh
          filename="meshes/L_shoulder_yaw.STL" />
      </geometry>
      <material
        name="">
        <color
          rgba="0.792156862745098 0.819607843137255 0.933333333333333 1" />
      </material>
    </visual>
    <collision>
      <origin
        xyz="0 0 0"
        rpy="0 0 0" />
      <geometry>
        <mesh
          filename="meshes/L_shoulder_yaw.STL" />
      </geometry>
    </collision>
  </link>
  <joint
    name="L_shoulder_yaw_joint"
    type="revolute">
    <origin
      xyz="0 0 -0.2505"
      rpy="0 0 0" />
    <parent
      link="L_shoulder_roll" />
    <child
      link="L_shoulder_yaw" />
    <axis
      xyz="0 0 1" />
    <limit
      lower="-1.57"
      upper="1.57"
      effort="20"
      velocity="11.5" />
  </joint>
  <link
    name="L_elbow_pitch">
    <inertial>
      <origin
        xyz="0 -0.000251 -0.078513"
        rpy="0 0 0" />
      <mass
        value="0.3055" />
      <inertia
        ixx="0.00177"
        ixy="0"
        ixz="0"
        iyy="0.0016"
        iyz="4E-06"
        izz="0.000308" />
    </inertial>
    <visual>
      <origin
        xyz="0 0 0"
        rpy="0 0 0" />
      <geometry>
        <mesh
          filename="meshes/L_elbow_pitch.STL" />
      </geometry>
      <material
        name="">
        <color
          rgba="0.792156862745098 0.819607843137255 0.933333333333333 1" />
      </material>
    </visual>
    <collision>
      <origin
        xyz="0 0 0"
        rpy="0 0 0" />
      <geometry>
        <mesh
          filename="meshes/L_elbow_pitch.STL" />
      </geometry>
    </collision>
  </link>
  <joint
    name="L_elbow_pitch_joint"
    type="revolute">
    <origin
      xyz="0 0 -0.0545"
      rpy="0 0 0" />
    <parent
      link="L_shoulder_yaw" />
    <child
      link="L_elbow_pitch" />
    <axis
      xyz="0 1 0" />
    <!-- <limit
      lower="-1.57"
      upper="0"
      effort="20"
      velocity="11.5" /> -->

    <limit
      lower="-1.57"
      upper="1.57"
      effort="20"
      velocity="11.5" />
  </joint>
  <link
    name="L_EE">
    <inertial>
      <origin
        xyz="0 0 -0.003521"
        rpy="0 0 0" />
      <mass
        value="0.0665" />
      <inertia
        ixx="3.8E-05"
        ixy="0"
        ixz="0"
        iyy="3.8E-05"
        iyz="0"
        izz="4.4E-05" />
    </inertial>
    <visual>
      <origin
        xyz="0 0 0"
        rpy="0 0 0" />
      <geometry>
        <mesh
          filename="meshes/L_EE.STL" />
      </geometry>
      <material
        name="">
        <color
          rgba="1 1 1 1" />
      </material>
    </visual>
    <collision>
      <origin
        xyz="0 0 0"
        rpy="0 0 0" />
      <geometry>
        <mesh
          filename="meshes/L_EE.STL" />
      </geometry>
    </collision>
  </link>
  <joint
    name="L_EE_joint"
    type="fixed">
    <origin
      xyz="0 0 -0.3"
      rpy="0 0 0" />
    <parent
      link="L_elbow_pitch" />
    <child
      link="L_EE" />
    <axis
      xyz="0 0 0" />
  </joint>
  <link
    name="R_shoulder_pitch">
    <inertial>
      <origin
        xyz="0.002185 -0.04921 0"
        rpy="0 0 0" />
      <mass
        value="0.4675" />
      <inertia
        ixx="0.000895"
        ixy="6.5E-05"
        ixz="0"
        iyy="0.000946"
        iyz="0"
        izz="0.001358" />
    </inertial>
    <visual>
      <origin
        xyz="0 0 0"
        rpy="0 0 0" />
      <geometry>
        <mesh
          filename="meshes/R_shoulder_pitch.STL" />
      </geometry>
      <material
        name="">
        <color
          rgba="0.792156862745098 0.819607843137255 0.933333333333333 1" />
      </material>
    </visual>
    <collision>
      <origin
        xyz="0 0 0"
        rpy="0 0 0" />
      <geometry>
        <mesh
          filename="meshes/R_shoulder_pitch.STL" />
      </geometry>
    </collision>
  </link>
  <joint
    name="R_shoulder_pitch_joint"
    type="revolute">
    <origin
      xyz="0 -0.16 0.36424"
      rpy="-0.34907 0 0" />
    <parent
      link="Torso" />
    <child
      link="R_shoulder_pitch" />
    <axis
      xyz="0 1 0" />
    <limit
      lower="-2.09"
      upper="2.09"
      effort="40"
      velocity="18" />
  </joint>
  <link
    name="R_shoulder_roll">
    <inertial>
      <origin
        xyz="0.000805 -0.000221 -0.080651"
        rpy="0 0 0" />
      <mass
        value="2.05" />
      <inertia
        ixx="0.020167"
        ixy="-5E-06"
        ixz="-0.00033"
        iyy="0.019962"
        iyz="-2.4E-05"
        izz="0.002330" />
    </inertial>
    <visual>
      <origin
        xyz="0 0 0"
        rpy="0 0 0" />
      <geometry>
        <mesh
          filename="meshes/R_shoulder_roll.STL" />
      </geometry>
      <material
        name="">
        <color
          rgba="0.792156862745098 0.819607843137255 0.933333333333333 1" />
      </material>
    </visual>
    <collision>
      <origin
        xyz="0 0 0"
        rpy="0 0 0" />
      <geometry>
        <mesh
          filename="meshes/R_shoulder_roll.STL" />
      </geometry>
    </collision>
  </link>
  <joint
    name="R_shoulder_roll_joint"
    type="revolute">
    <origin
      xyz="0 -0.082 0"
      rpy="-1.2217304764 0 0" />
    <parent
      link="R_shoulder_pitch" />
    <child
      link="R_shoulder_roll" />
    <axis
      xyz="1 0 0" />
    <limit
      lower="-1.92"
      upper="1.65"
      effort="40"
      velocity="18" />
  </joint>
  <link
    name="R_shoulder_yaw">
    <inertial>
      <origin
        xyz="-4.9E-05 -0.00212 -0.045518"
        rpy="0 0 0" />
      <mass
        value="0.6025" />
      <inertia
        ixx="0.000595"
        ixy="0"
        ixz="0"
        iyy="0.000485"
        iyz="-3E-06"
        izz="0.000471" />
    </inertial>
    <visual>
      <origin
        xyz="0 0 0"
        rpy="0 0 0" />
      <geometry>
        <mesh
          filename="meshes/R_shoulder_yaw.STL" />
      </geometry>
      <material
        name="">
        <color
          rgba="0.792156862745098 0.819607843137255 0.933333333333333 1" />
      </material>
    </visual>
    <collision>
      <origin
        xyz="0 0 0"
        rpy="0 0 0" />
      <geometry>
        <mesh
          filename="meshes/R_shoulder_yaw.STL" />
      </geometry>
    </collision>
  </link>
  <joint
    name="R_shoulder_yaw_joint"
    type="revolute">
    <origin
      xyz="0 0 -0.2505"
      rpy="0 0 0" />
    <parent
      link="R_shoulder_roll" />
    <child
      link="R_shoulder_yaw" />
    <axis
      xyz="0 0 1" />
    <limit
      lower="-1.57"
      upper="1.57"
      effort="20"
      velocity="11.5" />
  </joint>
  <link
    name="R_elbow_pitch">
    <inertial>
      <origin
        xyz="0 0.000188 -0.07906"
        rpy="0 0 0" />
      <mass
        value="0.304" />
      <inertia
        ixx="0.001765"
        ixy="0"
        ixz="0"
        iyy="0.001598"
        iyz="-3E-06"
        izz="0.000304" />
    </inertial>
    <visual>
      <origin
        xyz="0 0 0"
        rpy="0 0 0" />
      <geometry>
        <mesh
          filename="meshes/R_elbow_pitch.STL" />
      </geometry>
      <material
        name="">
        <color
          rgba="0.792156862745098 0.819607843137255 0.933333333333333 1" />
      </material>
    </visual>
    <collision>
      <origin
        xyz="0 0 0"
        rpy="0 0 0" />
      <geometry>
        <mesh
          filename="meshes/R_elbow_pitch.STL" />
      </geometry>
    </collision>
  </link>
  <joint
    name="R_elbow_pitch_joint"
    type="revolute">
    <origin
      xyz="0 0 -0.0545"
      rpy="0 0 0" />
    <parent
      link="R_shoulder_yaw" />
    <child
      link="R_elbow_pitch" />
    <axis
      xyz="0 1 0" />
    <!-- <limit
      lower="-1.57"
      upper="0"
      effort="20"
      velocity="11.5" /> -->
    <limit
      lower="-1.57"
      upper="1.57"
      effort="20"
      velocity="11.5" />
  </joint>
  <link
    name="R_EE">
    <inertial>
      <origin
        xyz="0 0 -0.003521"
        rpy="0 0 0" />
      <mass
        value="0.0665" />
      <inertia
        ixx="3.8E-05"
        ixy="0"
        ixz="0"
        iyy="3.8E-05"
        iyz="0"
        izz="4.4E-05" />
    </inertial>
    <visual>
      <origin
        xyz="0 0 0"
        rpy="0 0 0" />
      <geometry>
        <mesh
          filename="meshes/R_EE.STL" />
      </geometry>
      <material
        name="">
        <color
          rgba="1 1 1 1" />
      </material>
    </visual>
    <collision>
      <origin
        xyz="0 0 0"
        rpy="0 0 0" />
      <geometry>
        <mesh
          filename="meshes/R_EE.STL" />
      </geometry>
    </collision>
  </link>
  <joint
    name="R_EE_joint"
    type="fixed">
    <origin
      xyz="0 0 -0.3"
      rpy="0 0 0" />
    <parent
      link="R_elbow_pitch" />
    <child
      link="R_EE" />
    <axis
      xyz="0 0 0" />
  </joint>
  <link
    name="Head">
    <inertial>
      <origin
        xyz="0.022307 0.000408 0.104941"
        rpy="0 0 0" />
      <mass
        value="0.44842" />
      <inertia
        ixx="0.002696"
        ixy="-9E-06"
        ixz="-0.000288"
        iyy="0.00313"
        iyz="-7E-06"
        izz="0.001525" />
    </inertial>
    <visual>
      <origin
        xyz="0 0 0"
        rpy="0 0 0" />
      <geometry>
        <mesh
          filename="meshes/Head.STL" />
      </geometry>
      <material
        name="">
        <color
          rgba="0.792156862745098 0.819607843137255 0.933333333333333 1" />
      </material>
    </visual>
    <collision>
      <origin
        xyz="0 0 0"
        rpy="0 0 0" />
      <geometry>
        <mesh
          filename="meshes/Head.STL" />
      </geometry>
    </collision>
  </link>
  <joint
    name="Head_joint"
    type="fixed">
    <origin
      xyz="-0.0027205 0 0.45287"
      rpy="0 0 0" />
    <parent
      link="Torso" />
    <child
      link="Head" />
    <axis
      xyz="0 0 0" />
  </joint>
  <link
    name="L_hip">
    <inertial>
      <origin
        xyz="-0.086776 0.0 -0.070553"
        rpy="0 0 0" />
      <mass
        value="1.5262" />
      <inertia
        ixx="0.004080"
        ixy="0.0"
        ixz="-0.000987"
        iyy="0.003954"
        iyz="0.0"
        izz="0.002761" />
    </inertial>
    <visual>
      <origin
        xyz="0 0 0"
        rpy="0 0 0" />
      <geometry>
        <mesh
          filename="meshes/L_hip.STL" />
      </geometry>
      <material
        name="">
        <color
          rgba="0.792156862745098 0.819607843137255 0.933333333333333 1" />
      </material>
    </visual>
    <collision>
      <origin
        xyz="0 0 0"
        rpy="0 0 0" />
      <geometry>
        <mesh
          filename="meshes/L_hip.STL" />
      </geometry>
    </collision>
  </link>
  <joint
    name="L_hip_joint"
    type="revolute">
    <origin
      xyz="-0.0053471 0.1175 -0.0067"
      rpy="0 0 0" />
    <parent
      link="Pelvis" />
    <child
      link="L_hip" />
    <axis
      xyz="0 0 1" />
    <limit
      lower="-1.5"
      upper="1.5"
      effort="120"
      velocity="23" />
  </joint>
  <link
    name="L_hip2">
    <inertial>
      <origin
        xyz="0.076889 -0.034855 -0.014787"
        rpy="0 0 0" />
      <mass
        value="1.726000" />
      <inertia
        ixx="0.006963"
        ixy="0.000389"
        ixz="0.000363"
        iyy="0.004861"
        iyz="-0.000232"
        izz="0.007308" />
    </inertial>
    <visual>
      <origin
        xyz="0 0 0"
        rpy="0 0 0" />
      <geometry>
        <mesh
          filename="meshes/L_hip2.STL" />
      </geometry>
      <material
        name="">
        <color
          rgba="0.792156862745098 0.819607843137255 0.933333333333333 1" />
      </material>
    </visual>
    <collision>
      <origin
        xyz="0 0 0"
        rpy="0 0 0" />
      <geometry>
        <mesh
          filename="meshes/L_hip2.STL" />
      </geometry>
    </collision>
  </link>
  <joint
    name="L_hip2_joint"
    type="revolute">
    <origin
      xyz="-0.0763 0 -0.084"
      rpy="0 0 0" />
    <parent
      link="L_hip" />
    <child
      link="L_hip2" />
    <axis
      xyz="1 0 0" />
    <limit
      lower="-0.26"
      upper="0.69"
      effort="120"
      velocity="23" />
  </joint>
  <link
    name="L_thigh">
    <inertial>
      <origin
        xyz="0.000014 0.025209 -0.126499"
        rpy="0 0 0" />
      <mass
        value="4.750102" />
      <inertia
        ixx="0.107593"
        ixy="0.000001"
        ixz="0.000009"
        iyy="0.107651"
        iyz="-0.006073"
        izz="0.008614" />
    </inertial>
    <visual>
      <origin
        xyz="0 0 0"
        rpy="0 0 0" />
      <geometry>
        <mesh
          filename="meshes/L_thigh.STL" />
      </geometry>
      <material
        name="">
        <color
          rgba="0.792156862745098 0.819607843137255 0.933333333333333 1" />
      </material>
    </visual>
    <collision>
      <origin
        xyz="0 0 0"
        rpy="0 0 0" />
      <geometry>
        <mesh
          filename="meshes/L_thigh.STL" />
      </geometry>
    </collision>
  </link>
  <joint
    name="L_thigh_joint"
    type="revolute">
    <origin
      xyz="0.081 -0.0148 -0.0185"
      rpy="0 0.0 0" />
    <parent
      link="L_hip2" />
    <child
      link="L_thigh" />
    <axis
      xyz="0 1 0" />
    <limit
      lower="-1.25"
      upper="1.1"
      effort="120"
      velocity="23" />
  </joint>
  <link
    name="L_calf">
    <inertial>
      <origin
        xyz="-0.000226 0.016658 -0.148439"
        rpy="0 0 0" />
      <mass
        value="1.326656" />
      <inertia
        ixx="0.016199"
        ixy="0.000009"
        ixz="0.000014"
        iyy="0.016302"
        iyz="0.000005"
        izz="0.000772" />
    </inertial>
    <visual>
      <origin
        xyz="0 0 0"
        rpy="0 0 0" />
      <geometry>
        <mesh
          filename="meshes/L_calf.STL" />
      </geometry>
      <material
        name="">
        <color
          rgba="0.792156862745098 0.819607843137255 0.933333333333333 1" />
      </material>
    </visual>
    <collision>
      <origin
        xyz="0 0 0"
        rpy="0 0 0" />
      <geometry>
        <mesh
          filename="meshes/L_calf.STL" />
      </geometry>
    </collision>
  </link>
  <joint
    name="L_calf_joint"
    type="revolute">
    <origin
      xyz="0 0 -0.35"
      rpy="0 0.0 0" />
    <parent
      link="L_thigh" />
    <child
      link="L_calf" />
    <axis
      xyz="0 1 0" />
    <limit
      lower="-1.571"
      upper="1.571"
      effort="180"
      velocity="15" />
  </joint>
  <link
    name="L_toe">
    <inertial>
      <origin
        xyz="0.002701 0.015076 -0.032168"
        rpy="0 0 0" />
      <mass
        value="0.520" />
      <inertia
        ixx="0.000162"
        ixy="0.000016"
        ixz="0.000083"
        iyy="0.001485"
        iyz="0.000003"
        izz="0.001511" />
    </inertial>
    <visual>
      <origin
        xyz="0 0 0"
        rpy="0 0 0" />
      <geometry>
        <mesh
          filename="meshes/L_toe.STL" />
      </geometry>
      <material
        name="">
        <color
          rgba="0.792156862745098 0.819607843137255 0.933333333333333 1" />
      </material>
    </visual>
    <collision>
      <origin
        xyz="0 0 0"
        rpy="0 0 0" />
      <geometry>
        <mesh
          filename="meshes/L_toe.STL" />
      </geometry>
    </collision>
  </link>
  <joint
    name="L_toe_joint"
    type="revolute">
    <origin
      xyz="0 0 -0.35"
      rpy="0 0.0 0" />
    <parent
      link="L_calf" />
    <child
      link="L_toe" />
    <axis
      xyz="0 1 0" />
    <limit
      lower="-0.9"
      upper="0.9"
      effort="36"
      velocity="11.5" />
  </joint>
    <link name="L_end_effector">
    <visual>
      <origin xyz="0 0 0" rpy="0 0 0" />
      <geometry>
        <sphere radius="0.0001" />
      </geometry>
      <material name=""> 
        <color rgba="0 0 0 0" />
      </material>
    </visual>
  </link>
  <joint name="L_end_joint"
    type="fixed">
    <origin
      xyz="0 0 -0.049"
      rpy="0 0 0" />
    <parent
      link="L_toe" />
    <child
      link="L_end_effector" />
    <axis
      xyz="0 0 0" />
    <limit
      lower="0"
      upper="0"
      effort="0"
      velocity="0" />
  </joint>
  <link
    name="R_hip">
    <inertial>
      <origin
        xyz="-0.086776 0.0 -0.070553"
        rpy="0 0 0" />
      <mass
        value="1.5262" />
      <inertia
        ixx="0.004080"
        ixy="0.0"
        ixz="-0.000987"
        iyy="0.003954"
        iyz="0.0"
        izz="0.002761" />
    </inertial>
    <visual>
      <origin
        xyz="0 0 0"
        rpy="0 0 0" />
      <geometry>
        <mesh
          filename="meshes/R_hip.STL" />
      </geometry>
      <material
        name="">
        <color
          rgba="0.79216 0.81961 0.93333 1" />
      </material>
    </visual>
    <collision>
      <origin
        xyz="0 0 0"
        rpy="0 0 0" />
      <geometry>
        <mesh
          filename="meshes/R_hip.STL" />
      </geometry>
    </collision>
  </link>
  <joint
    name="R_hip_joint"
    type="revolute">
    <origin
      xyz="-0.0053471 -0.1175 -0.0067"
      rpy="0 0 0" />
    <parent
      link="Pelvis" />
    <child
      link="R_hip" />
    <axis
      xyz="0 0 1" />
    <limit
      lower="-1.5"
      upper="1.5"
      effort="120"
      velocity="23" />
  </joint>
  <link
    name="R_hip2">
    <inertial>
      <origin
        xyz="0.076889 0.034855 -0.014787"
        rpy="0 0 0" />
      <mass
        value="1.726000" />
      <inertia
        ixx="0.006963"
        ixy="-0.000389"
        ixz="0.000363"
        iyy="0.004861"
        iyz="0.000232"
        izz="0.007308" />
    </inertial>
    <visual>
      <origin
        xyz="0 0 0"
        rpy="0 0 0" />
      <geometry>
        <mesh
          filename="meshes/R_hip2.STL" />
      </geometry>
      <material
        name="">
        <color
          rgba="0.792156862745098 0.819607843137255 0.933333333333333 1" />
      </material>
    </visual>
    <collision>
      <origin
        xyz="0 0 0"
        rpy="0 0 0" />
      <geometry>
        <mesh
          filename="meshes/R_hip2.STL" />
      </geometry>
    </collision>
  </link>
  <joint
    name="R_hip2_joint"
    type="revolute">
    <origin
      xyz="-0.0763 0 -0.084"
      rpy="0 0 0" />
    <parent
      link="R_hip" />
    <child
      link="R_hip2" />
    <axis
      xyz="1 0 0" />
    <limit
      lower="-0.69"
      upper="0.26"
      effort="120"
      velocity="23" />
  </joint>
  <link
    name="R_thigh">
    <inertial>
      <origin
        xyz="-0.000014 -0.025209 -0.126499"
        rpy="0 0 0" />
      <mass
        value="4.750102" />
      <inertia
        ixx="0.107593"
        ixy="0.000001"
        ixz="-0.000009"
        iyy="0.107651"
        iyz="0.006073"
        izz="0.008614" />
    </inertial>
    <visual>
      <origin
        xyz="0 0 0"
        rpy="0 0 0" />
      <geometry>
        <mesh
          filename="meshes/R_thigh.STL" />
      </geometry>
      <material
        name="">
        <color
          rgba="0.792156862745098 0.819607843137255 0.933333333333333 1" />
      </material>
    </visual>
    <collision>
      <origin
        xyz="0 0 0"
        rpy="0 0 0" />
      <geometry>
        <mesh
          filename="meshes/R_thigh.STL" />
      </geometry>
    </collision>
  </link>
  <joint
    name="R_thigh_joint"
    type="revolute">
    <origin
      xyz="0.081 0.0148 -0.0185"
      rpy="0 0.0 0" />
    <parent
      link="R_hip2" />
    <child
      link="R_thigh" />
    <axis
      xyz="0 1 0" />
    <limit
      lower="-1.25"
      upper="1.1"
      effort="120"
      velocity="23" />
  </joint>
  <link
    name="R_calf">
    <inertial>
      <origin
        xyz="0.000226 -0.016658 -0.148439"
        rpy="0 0 0" />
      <mass
        value="1.326656" />
      <inertia
        ixx="0.016199"
        ixy="0.000009"
        ixz="-0.000014"
        iyy="0.016302"
        iyz="-0.000005"
        izz="0.000772" />
    </inertial>
    <visual>
      <origin
        xyz="0 0 0"
        rpy="0 0 0" />
      <geometry>
        <mesh
          filename="meshes/R_calf.STL" />
      </geometry>
      <material
        name="">
        <color
          rgba="0.792156862745098 0.819607843137255 0.933333333333333 1" />
      </material>
    </visual>
    <collision>
      <origin
        xyz="0 0 0"
        rpy="0 0 0" />
      <geometry>
        <mesh
          filename="meshes/R_calf.STL" />
      </geometry>
    </collision>
  </link>
  <joint
    name="R_calf_joint"
    type="revolute">
    <origin
      xyz="0 0 -0.35"
      rpy="0 0.0 0" />
    <parent
      link="R_thigh" />
    <child
      link="R_calf" />
    <axis
      xyz="0 1 0" />
    <limit
      lower="-1.571"
      upper="1.571"
      effort="180"
      velocity="15" />
  </joint>
  <link
    name="R_toe">
    <inertial>
      <origin
        xyz="0.002387 -0.015128 -0.032168"
        rpy="0 0 0" />
      <mass
        value="0.520" />
      <inertia
        ixx="0.000162"
        ixy="0.000012"
        ixz="0.000083"
        iyy="0.001485"
        iyz="-0.000004"
        izz="0.001511" />
    </inertial>
    <visual>
      <origin
        xyz="0 0 0"
        rpy="0 0 0" />
      <geometry>
        <mesh
          filename="meshes/R_toe.STL" />
      </geometry>
      <material
        name="">
        <color
          rgba="0.792156862745098 0.819607843137255 0.933333333333333 1" />
      </material>
    </visual>
    <collision>
      <origin
        xyz="0 0 0"
        rpy="0 0 0" />
      <geometry>
        <mesh
          filename="meshes/R_toe.STL" />
      </geometry>
    </collision>
  </link>
  <joint
    name="R_toe_joint"
    type="revolute">
    <origin
      xyz="0 0 -0.35"
      rpy="0 0.0 0" />
    <parent
      link="R_calf" />
    <child
      link="R_toe" />
    <axis
      xyz="0 1 0" />
    <limit
      lower="-0.9"
      upper="0.9"
      effort="36"
      velocity="11.5" />
  </joint>
    <link name="R_end_effector">
    <visual>
      <origin xyz="0 0 0" rpy="0 0 0" />
      <geometry>
        <sphere radius="0.0001" />
      </geometry>
      <material name=""> 
        <color rgba="0 0 0 0" />
      </material>
    </visual>
  </link>
  <joint name="R_end_joint"
    type="fixed">
    <origin
      xyz="0 0 -0.049"
      rpy="0 0 0" />
    <parent
      link="R_toe" />
    <child
      link="R_end_effector" />
    <axis
      xyz="0 0 0" />
    <limit
      lower="0"
      upper="0"
      effort="0"
      velocity="0" />
  </joint>
</robot>