<mujoco model="Wholebody_URDF_1125">
  <compiler angle="radian" meshdir="meshes"/>
  <default>
    <motor ctrlrange="-1 1" ctrllimited="true"/>
    <joint actuatorfrclimited="true" type="hinge"/>
  </default>

  <asset>
    <mesh name="Pelvis" file="Pelvis.STL" />
    <mesh name="Torso" file="Torso.STL" />
    <mesh name="L_shoulder_pitch" file="L_shoulder_pitch.STL" />
    <mesh name="L_shoulder_roll" file="L_shoulder_roll.STL" />
    <mesh name="L_shoulder_yaw" file="L_shoulder_yaw.STL" />
    <mesh name="L_elbow_pitch" file="L_elbow_pitch.STL" />
    <mesh name="L_EE" file="L_EE.STL" />
    <mesh name="R_shoulder_pitch" file="R_shoulder_pitch.STL" />
    <mesh name="R_shoulder_roll" file="R_shoulder_roll.STL" />
    <mesh name="R_shoulder_yaw" file="R_shoulder_yaw.STL" />
    <mesh name="R_elbow_pitch" file="R_elbow_pitch.STL" />
    <mesh name="R_EE" file="R_EE.STL" />
    <mesh name="Head" file="Head.STL" />
    <mesh name="L_hip" file="L_hip.STL" />
    <mesh name="L_hip2" file="L_hip2.STL" />
    <mesh name="L_thigh" file="L_thigh.STL" />
    <mesh name="L_calf" file="L_calf.STL" />
    <mesh name="L_toe" file="L_toe.STL" />
    <mesh name="R_hip" file="R_hip.STL" />
    <mesh name="R_hip2" file="R_hip2.STL" />
    <mesh name="R_thigh" file="R_thigh.STL" />
    <mesh name="R_calf" file="R_calf.STL" />
    <mesh name="R_toe" file="R_toe.STL" />
  </asset>

  <worldbody>
    <body name="pelvis" pos="0 0 0.9562755197700887" quat="1 0 0 0">
      <freejoint name="pelvis" />
      <site name="imu" size="0.01" pos="0 0 0" />
      <geom type="mesh" rgba="0.79216 0.81961 0.93333 1" mesh="Pelvis" contype="1" conaffinity="0" density="0" group="1"  />
      <geom type="mesh" rgba="0.79216 0.81961 0.93333 1" mesh="Pelvis" />
      <body name="Torso" pos="0 0 0.0825">
        <inertial pos="-0.0146338 -0.000492904 0.243069" quat="0.999618 -0.000634815 0.0276164 0.00129989" mass="13.8715" diaginertia="0.275975 0.214949 0.100108" />
        <joint name="Waist_joint" pos="0 0 0" axis="0 0 1" range="-1.57 1.57" actuatorfrcrange="-100 100" />
        <geom type="mesh" rgba="0.792157 0.819608 0.933333 1" mesh="Torso" contype="1" conaffinity="0" density="0" group="1"  />
        <geom type="mesh" rgba="0.792157 0.819608 0.933333 1" mesh="Torso" />
        <geom pos="-0.0027205 0 0.45287" quat="1 0 0 0" type="mesh" rgba="0.792157 0.819608 0.933333 1" mesh="Head" contype="1" conaffinity="0" density="0" group="1"  />
        <geom type="mesh" rgba="0.792157 0.819608 0.933333 1" mesh="Head" pos="-0.0027205 0 0.45287" quat="1 0 0 0" />
        <body name="L_shoulder_pitch" pos="0 0.16 0.36424" quat="0.984807 0.17365 0 0">
          <inertial pos="0.002264 0.049276 0" quat="-0.207324 0.67603 0.207324 0.67603" mass="0.4695" diaginertia="0.001364 0.000995007 0.000854993" />
          <joint name="L_shoulder_pitch_joint" pos="0 0 0" axis="0 1 0" range="-2.09 2.09" actuatorfrcrange="-40 40" />
          <geom type="mesh" rgba="0.792157 0.819608 0.933333 1" mesh="L_shoulder_pitch" contype="1" conaffinity="0" density="0" group="1"  />
          <geom type="mesh" rgba="0.792157 0.819608 0.933333 1" mesh="L_shoulder_pitch" />
          <body name="L_shoulder_roll" pos="0 0.082 0" quat="0.819152 0.573576 0 0">
            <inertial pos="0.000605 6.8e-05 -0.08074" quat="0.999867 0.00114717 0.00883611 -0.013694" mass="2.05" diaginertia="0.0202637 0.020052 0.00234531" />
            <joint name="L_shoulder_roll_joint" pos="0 0 0" axis="1 0 0" range="-1.65 1.92" actuatorfrcrange="-40 40" />
            <geom type="mesh" rgba="0.792157 0.819608 0.933333 1" mesh="L_shoulder_roll" contype="1" conaffinity="0" density="0" group="1"  />
            <geom type="mesh" rgba="0.792157 0.819608 0.933333 1" mesh="L_shoulder_roll" />
            <body name="L_shoulder_yaw" pos="0 0 -0.2505">
              <inertial pos="4.9e-05 0.002116 -0.045474" quat="0.994881 0.10105 0 0" mass="0.602" diaginertia="0.000595 0.000485616 0.000470384" />
              <joint name="L_shoulder_yaw_joint" pos="0 0 0" axis="0 0 1" range="-1.57 1.57" actuatorfrcrange="-20 20" />
              <geom type="mesh" rgba="0.792157 0.819608 0.933333 1" mesh="L_shoulder_yaw" contype="1" conaffinity="0" density="0" group="1"  />
              <geom type="mesh" rgba="0.792157 0.819608 0.933333 1" mesh="L_shoulder_yaw" />
              <body name="L_elbow_pitch" pos="0 0 -0.0545">
                <inertial pos="0 -0.00020613 -0.118736" quat="1 0.000874403 0 0" mass="0.372" diaginertia="0.00457294 0.00440295 0.000351991" />
                <joint name="L_elbow_pitch_joint" pos="0 0 0" axis="0 1 0" range="-1.57 1.57" actuatorfrcrange="-20 20" />
                <geom type="mesh" rgba="0.792157 0.819608 0.933333 1" mesh="L_elbow_pitch" contype="1" conaffinity="0" density="0" group="1"  />
                <geom type="mesh" rgba="0.792157 0.819608 0.933333 1" mesh="L_elbow_pitch" />
                <geom pos="0 0 -0.3" quat="1 0 0 0" type="mesh" rgba="1 1 1 1" mesh="L_EE" contype="1" conaffinity="0" density="0" group="1"  />
                <geom type="mesh" rgba="1 1 1 1" mesh="L_EE" pos="0 0 -0.3" quat="1 0 0 0" />
                <body name="L_EE" pos="0 0 -0.3"></body>
              </body>
            </body>
          </body>
        </body>
        <body name="R_shoulder_pitch" pos="0 -0.16 0.36424" quat="0.984807 -0.17365 0 0">
          <inertial pos="0.002185 -0.04921 0" quat="0.208447 0.675685 -0.208447 0.675685" mass="0.4675" diaginertia="0.001358 0.000990323 0.000850677" />
          <joint name="R_shoulder_pitch_joint" pos="0 0 0" axis="0 1 0" range="-2.09 2.09" actuatorfrcrange="-40 40" />
          <geom type="mesh" rgba="0.792157 0.819608 0.933333 1" mesh="R_shoulder_pitch" contype="1" conaffinity="0" density="0" group="1"  />
          <geom type="mesh" rgba="0.792157 0.819608 0.933333 1" mesh="R_shoulder_pitch" />
          <body name="R_shoulder_roll" pos="0 -0.082 0" quat="0.819152 -0.573576 0 0">
            <inertial pos="0.000805 -0.000221 -0.080651" quat="0.999899 -0.000782491 0.00923818 -0.0107774" mass="2.05" diaginertia="0.0201732 0.0199619 0.00232386" />
            <joint name="R_shoulder_roll_joint" pos="0 0 0" axis="1 0 0" range="-1.92 1.65" actuatorfrcrange="-40 40" />
            <geom type="mesh" rgba="0.792157 0.819608 0.933333 1" mesh="R_shoulder_roll" contype="1" conaffinity="0" density="0" group="1"  />
            <geom type="mesh" rgba="0.792157 0.819608 0.933333 1" mesh="R_shoulder_roll" />
            <body name="R_shoulder_yaw" pos="0 0 -0.2505">
              <inertial pos="-4.9e-05 -0.00212 -0.045518" quat="0.994881 -0.10105 0 0" mass="0.6025" diaginertia="0.000595 0.000485616 0.000470384" />
              <joint name="R_shoulder_yaw_joint" pos="0 0 0" axis="0 0 1" range="-1.57 1.57" actuatorfrcrange="-20 20" />
              <geom type="mesh" rgba="0.792157 0.819608 0.933333 1" mesh="R_shoulder_yaw" contype="1" conaffinity="0" density="0" group="1"  />
              <geom type="mesh" rgba="0.792157 0.819608 0.933333 1" mesh="R_shoulder_yaw" />
              <body name="R_elbow_pitch" pos="0 0 -0.0545">
                <inertial pos="0 0.000154256 -0.119348" quat="1 -0.000656726 0 0" mass="0.3705" diaginertia="0.00455209 0.0043851 0.000347995" />
                <joint name="R_elbow_pitch_joint" pos="0 0 0" axis="0 1 0" range="-1.57 1.57" actuatorfrcrange="-20 20" />
                <geom type="mesh" rgba="0.792157 0.819608 0.933333 1" mesh="R_elbow_pitch" contype="1" conaffinity="0" density="0" group="1"  />
                <geom type="mesh" rgba="0.792157 0.819608 0.933333 1" mesh="R_elbow_pitch" />
                <geom pos="0 0 -0.3" quat="1 0 0 0" type="mesh" rgba="1 1 1 1" mesh="R_EE" contype="1" conaffinity="0" density="0" group="1"  />
                <geom type="mesh" rgba="1 1 1 1" mesh="R_EE" pos="0 0 -0.3" quat="1 0 0 0" />
                <body name="R_EE" pos="0 0 -0.3"></body>
              </body>
            </body>
          </body>
        </body>
      </body>
      <body name="L_hip" pos="-0.0053471 0.1175 -0.0067">
        <inertial pos="-0.086776 0 -0.070553" quat="0.970032 0 0.242979 0" mass="1.5262" diaginertia="0.00460756 0.003954 0.00223344" />
        <joint name="L_hip_joint" pos="0 0 0" axis="0 0 1" range="-1.5 1.5" actuatorfrcrange="-120 120" />
        <geom type="mesh" rgba="0.792157 0.819608 0.933333 1" mesh="L_hip" contype="1" conaffinity="0" density="0" group="1"  />
        <geom type="mesh" rgba="0.792157 0.819608 0.933333 1" mesh="L_hip" />
        <body name="L_hip2" pos="-0.0763 0 -0.084">
          <inertial pos="0.076889 -0.034855 -0.014787" quat="0.547127 0.68477 -0.298338 0.377805" mass="1.726" diaginertia="0.00753746 0.00683732 0.00475722" />
          <joint name="L_hip2_joint" pos="0 0 0" axis="1 0 0" range="-0.26 0.69" actuatorfrcrange="-120 120" />
          <geom type="mesh" rgba="0.792157 0.819608 0.933333 1" mesh="L_hip2" contype="1" conaffinity="0" density="0" group="1"  />
          <geom type="mesh" rgba="0.792157 0.819608 0.933333 1" mesh="L_hip2" />
          <body name="L_thigh" pos="0.081 -0.0148 -0.0185">
            <inertial pos="1.4e-05 0.025209 -0.126499" quat="0.707147 -0.0216125 0.0215255 0.706408" mass="4.7501" diaginertia="0.108022 0.107593 0.00824299" />
            <joint name="L_thigh_joint" pos="0 0 0" axis="0 1 0" range="-1.25 1.1" actuatorfrcrange="-120 120" />
            <geom type="mesh" rgba="0.792157 0.819608 0.933333 1" mesh="L_thigh" contype="1" conaffinity="0" density="0" group="1"  />
            <geom type="mesh" rgba="0.792157 0.819608 0.933333 1" mesh="L_thigh" />
            <body name="L_calf" pos="0 0 -0.35">
              <inertial pos="-0.000226 0.016658 -0.148439" quat="0.737038 -0.00018815 -0.000442981 0.675851" mass="1.32666" diaginertia="0.0163028 0.0161982 0.000771986" />
              <joint name="L_calf_joint" pos="0 0 0" axis="0 1 0" range="-1.571 1.571" actuatorfrcrange="-180 180" />
              <geom type="mesh" rgba="0.792157 0.819608 0.933333 1" mesh="L_calf" contype="1" conaffinity="0" density="0" group="1"  />
              <geom type="mesh" rgba="0.792157 0.819608 0.933333 1" mesh="L_calf" />
              <body name="L_toe" pos="0 0 -0.35">
                <inertial pos="0.002701 0.015076 -0.032168" quat="0.0474034 0.727206 0.0417405 0.683507" mass="0.52" diaginertia="0.00151659 0.00148468 0.000156725" />
                <joint name="L_toe_joint" pos="0 0 0" axis="0 1 0" range="-0.9 0.9" actuatorfrcrange="-36 36" />
                <geom type="mesh" rgba="0.792157 0.819608 0.933333 1" mesh="L_toe" contype="1" conaffinity="0" density="0" group="1"  />
                <geom type="mesh" rgba="0.792157 0.819608 0.933333 1" mesh="L_toe" />
              </body>
            </body>
          </body>
        </body>
      </body>
      <body name="R_hip" pos="-0.0053471 -0.1175 -0.0067">
        <inertial pos="-0.086776 0 -0.070553" quat="0.970032 0 0.242979 0" mass="1.5262" diaginertia="0.00460756 0.003954 0.00223344" />
        <joint name="R_hip_joint" pos="0 0 0" axis="0 0 1" range="-1.5 1.5" actuatorfrcrange="-120 120" />
        <geom type="mesh" rgba="0.79216 0.81961 0.93333 1" mesh="R_hip" contype="1" conaffinity="0" density="0" group="1"  />
        <geom type="mesh" rgba="0.79216 0.81961 0.93333 1" mesh="R_hip" />
        <body name="R_hip2" pos="-0.0763 0 -0.084">
          <inertial pos="0.076889 0.034855 -0.014787" quat="0.68477 0.547127 -0.377805 0.298338" mass="1.726" diaginertia="0.00753746 0.00683732 0.00475722" />
          <joint name="R_hip2_joint" pos="0 0 0" axis="1 0 0" range="-0.69 0.26" actuatorfrcrange="-120 120" />
          <geom type="mesh" rgba="0.792157 0.819608 0.933333 1" mesh="R_hip2" contype="1" conaffinity="0" density="0" group="1"  />
          <geom type="mesh" rgba="0.792157 0.819608 0.933333 1" mesh="R_hip2" />
          <body name="R_thigh" pos="0.081 0.0148 -0.0185">
            <inertial pos="-1.4e-05 -0.025209 -0.126499" quat="0.707147 0.0216125 -0.0215255 0.706408" mass="4.7501" diaginertia="0.108022 0.107593 0.00824299" />
            <joint name="R_thigh_joint" pos="0 0 0" axis="0 1 0" range="-1.25 1.1" actuatorfrcrange="-120 120" />
            <geom type="mesh" rgba="0.792157 0.819608 0.933333 1" mesh="R_thigh" contype="1" conaffinity="0" density="0" group="1"  />
            <geom type="mesh" rgba="0.792157 0.819608 0.933333 1" mesh="R_thigh" />
            <body name="R_calf" pos="0 0 -0.35">
              <inertial pos="0.000226 -0.016658 -0.148439" quat="0.737038 0.00018815 0.000442981 0.675851" mass="1.32666" diaginertia="0.0163028 0.0161982 0.000771986" />
              <joint name="R_calf_joint" pos="0 0 0" axis="0 1 0" range="-1.571 1.571" actuatorfrcrange="-180 180" />
              <geom type="mesh" rgba="0.792157 0.819608 0.933333 1" mesh="R_calf" contype="1" conaffinity="0" density="0" group="1"  />
              <geom type="mesh" rgba="0.792157 0.819608 0.933333 1" mesh="R_calf" />
              <body name="R_toe" pos="0 0 -0.35">
                <inertial pos="0.002387 -0.015128 -0.032168" quat="-0.0321524 0.727274 -0.0408907 0.684373" mass="0.52" diaginertia="0.00151643 0.00148477 0.0001568" />
                <joint name="R_toe_joint" pos="0 0 0" axis="0 1 0" range="-0.9 0.9" actuatorfrcrange="-36 36" />
                <geom type="mesh" rgba="0.792157 0.819608 0.933333 1" mesh="R_toe" contype="1" conaffinity="0" density="0" group="1"  />
                <geom type="mesh" rgba="0.792157 0.819608 0.933333 1" mesh="R_toe" />
              </body>
            </body>
          </body>
        </body>
      </body>
    </body>
  </worldbody>

  <actuator>
    <motor name="Waist_joint" joint="Waist_joint" ctrllimited="true" ctrlrange="-100 100" gear="1" />
    <motor name="L_shoulder_pitch_joint" joint="L_shoulder_pitch_joint" ctrllimited="true" ctrlrange="-40 40" gear="1" />
    <motor name="L_shoulder_roll_joint" joint="L_shoulder_roll_joint" ctrllimited="true" ctrlrange="-40 40" gear="1" />
    <motor name="L_shoulder_yaw_joint" joint="L_shoulder_yaw_joint" ctrllimited="true" ctrlrange="-20 20" gear="1" />
    <motor name="L_elbow_pitch_joint" joint="L_elbow_pitch_joint" ctrllimited="true" ctrlrange="-20 20" gear="1" />
    <motor name="R_shoulder_pitch_joint" joint="R_shoulder_pitch_joint" ctrllimited="true" ctrlrange="-40 40" gear="1" />
    <motor name="R_shoulder_roll_joint" joint="R_shoulder_roll_joint" ctrllimited="true" ctrlrange="-40 40" gear="1" />
    <motor name="R_shoulder_yaw_joint" joint="R_shoulder_yaw_joint" ctrllimited="true" ctrlrange="-20 20" gear="1" />
    <motor name="R_elbow_pitch_joint" joint="R_elbow_pitch_joint" ctrllimited="true" ctrlrange="-20 20" gear="1" />
    <motor name="L_hip_joint" joint="L_hip_joint" ctrllimited="true" ctrlrange="-120 120" gear="1" />
    <motor name="L_hip2_joint" joint="L_hip2_joint" ctrllimited="true" ctrlrange="-120 120" gear="1" />
    <motor name="L_thigh_joint" joint="L_thigh_joint" ctrllimited="true" ctrlrange="-120 120" gear="1" />
    <motor name="L_calf_joint" joint="L_calf_joint" ctrllimited="true" ctrlrange="-180 180" gear="1" />
    <motor name="L_toe_joint" joint="L_toe_joint" ctrllimited="true" ctrlrange="-36 36" gear="1" />
    <motor name="R_hip_joint" joint="R_hip_joint" ctrllimited="true" ctrlrange="-120 120" gear="1" />
    <motor name="R_hip2_joint" joint="R_hip2_joint" ctrllimited="true" ctrlrange="-120 120" gear="1" />
    <motor name="R_thigh_joint" joint="R_thigh_joint" ctrllimited="true" ctrlrange="-120 120" gear="1" />
    <motor name="R_calf_joint" joint="R_calf_joint" ctrllimited="true" ctrlrange="-180 180" gear="1" />
    <motor name="R_toe_joint" joint="R_toe_joint" ctrllimited="true" ctrlrange="-36 36" gear="1" />
  </actuator>

  <sensor>
    <actuatorpos name="Waist_joint_p" actuator="Waist_joint" />
    <actuatorvel name="Waist_joint_v" actuator="Waist_joint" />
    <actuatorfrc name="Waist_joint_f" actuator="Waist_joint" noise="0.001" />
    <actuatorpos name="L_shoulder_pitch_joint_p" actuator="L_shoulder_pitch_joint" />
    <actuatorvel name="L_shoulder_pitch_joint_v" actuator="L_shoulder_pitch_joint" />
    <actuatorfrc name="L_shoulder_pitch_joint_f" actuator="L_shoulder_pitch_joint" noise="0.001" />
    <actuatorpos name="L_shoulder_roll_joint_p" actuator="L_shoulder_roll_joint" />
    <actuatorvel name="L_shoulder_roll_joint_v" actuator="L_shoulder_roll_joint" />
    <actuatorfrc name="L_shoulder_roll_joint_f" actuator="L_shoulder_roll_joint" noise="0.001" />
    <actuatorpos name="L_shoulder_yaw_joint_p" actuator="L_shoulder_yaw_joint" />
    <actuatorvel name="L_shoulder_yaw_joint_v" actuator="L_shoulder_yaw_joint" />
    <actuatorfrc name="L_shoulder_yaw_joint_f" actuator="L_shoulder_yaw_joint" noise="0.001" />
    <actuatorpos name="L_elbow_pitch_joint_p" actuator="L_elbow_pitch_joint" />
    <actuatorvel name="L_elbow_pitch_joint_v" actuator="L_elbow_pitch_joint" />
    <actuatorfrc name="L_elbow_pitch_joint_f" actuator="L_elbow_pitch_joint" noise="0.001" />
    <actuatorpos name="R_shoulder_pitch_joint_p" actuator="R_shoulder_pitch_joint" />
    <actuatorvel name="R_shoulder_pitch_joint_v" actuator="R_shoulder_pitch_joint" />
    <actuatorfrc name="R_shoulder_pitch_joint_f" actuator="R_shoulder_pitch_joint" noise="0.001" />
    <actuatorpos name="R_shoulder_roll_joint_p" actuator="R_shoulder_roll_joint" />
    <actuatorvel name="R_shoulder_roll_joint_v" actuator="R_shoulder_roll_joint" />
    <actuatorfrc name="R_shoulder_roll_joint_f" actuator="R_shoulder_roll_joint" noise="0.001" />
    <actuatorpos name="R_shoulder_yaw_joint_p" actuator="R_shoulder_yaw_joint" />
    <actuatorvel name="R_shoulder_yaw_joint_v" actuator="R_shoulder_yaw_joint" />
    <actuatorfrc name="R_shoulder_yaw_joint_f" actuator="R_shoulder_yaw_joint" noise="0.001" />
    <actuatorpos name="R_elbow_pitch_joint_p" actuator="R_elbow_pitch_joint" />
    <actuatorvel name="R_elbow_pitch_joint_v" actuator="R_elbow_pitch_joint" />
    <actuatorfrc name="R_elbow_pitch_joint_f" actuator="R_elbow_pitch_joint" noise="0.001" />
    <actuatorpos name="L_hip_joint_p" actuator="L_hip_joint" />
    <actuatorvel name="L_hip_joint_v" actuator="L_hip_joint" />
    <actuatorfrc name="L_hip_joint_f" actuator="L_hip_joint" noise="0.001" />
    <actuatorpos name="L_hip2_joint_p" actuator="L_hip2_joint" />
    <actuatorvel name="L_hip2_joint_v" actuator="L_hip2_joint" />
    <actuatorfrc name="L_hip2_joint_f" actuator="L_hip2_joint" noise="0.001" />
    <actuatorpos name="L_thigh_joint_p" actuator="L_thigh_joint" />
    <actuatorvel name="L_thigh_joint_v" actuator="L_thigh_joint" />
    <actuatorfrc name="L_thigh_joint_f" actuator="L_thigh_joint" noise="0.001" />
    <actuatorpos name="L_calf_joint_p" actuator="L_calf_joint" />
    <actuatorvel name="L_calf_joint_v" actuator="L_calf_joint" />
    <actuatorfrc name="L_calf_joint_f" actuator="L_calf_joint" noise="0.001" />
    <actuatorpos name="L_toe_joint_p" actuator="L_toe_joint" />
    <actuatorvel name="L_toe_joint_v" actuator="L_toe_joint" />
    <actuatorfrc name="L_toe_joint_f" actuator="L_toe_joint" noise="0.001" />
    <actuatorpos name="R_hip_joint_p" actuator="R_hip_joint" />
    <actuatorvel name="R_hip_joint_v" actuator="R_hip_joint" />
    <actuatorfrc name="R_hip_joint_f" actuator="R_hip_joint" noise="0.001" />
    <actuatorpos name="R_hip2_joint_p" actuator="R_hip2_joint" />
    <actuatorvel name="R_hip2_joint_v" actuator="R_hip2_joint" />
    <actuatorfrc name="R_hip2_joint_f" actuator="R_hip2_joint" noise="0.001" />
    <actuatorpos name="R_thigh_joint_p" actuator="R_thigh_joint" />
    <actuatorvel name="R_thigh_joint_v" actuator="R_thigh_joint" />
    <actuatorfrc name="R_thigh_joint_f" actuator="R_thigh_joint" noise="0.001" />
    <actuatorpos name="R_calf_joint_p" actuator="R_calf_joint" />
    <actuatorvel name="R_calf_joint_v" actuator="R_calf_joint" />
    <actuatorfrc name="R_calf_joint_f" actuator="R_calf_joint" noise="0.001" />
    <actuatorpos name="R_toe_joint_p" actuator="R_toe_joint" />
    <actuatorvel name="R_toe_joint_v" actuator="R_toe_joint" />
    <actuatorfrc name="R_toe_joint_f" actuator="R_toe_joint" noise="0.001" />
    <framequat name="orientation" objtype="site" noise="0.001" objname="imu" />
    <gyro name="angular-velocity" site="imu" noise="0.005" cutoff="34.9" />
  </sensor>
  <!-- setup scene -->
  <statistic center="1.0 0.7 1.0" extent="0.8"/>
  <visual>
    <headlight diffuse="0.6 0.6 0.6" ambient="0.1 0.1 0.1" specular="0.9 0.9 0.9"/>
    <rgba haze="0.15 0.25 0.35 1"/>
    <global azimuth="-140" elevation="-20" offwidth="2080" offheight="1170"/>
  </visual>
  <asset>
     <texture type="skybox" builtin="gradient" rgb1="1 1 1" rgb2="1 1 1" width="800" height="800"/>
    <texture type="2d" name="groundplane" builtin="checker" mark="edge" rgb1="1 1 1" rgb2="1 1 1" markrgb="0 0 0"
      width="300" height="300"/>
    <material name="groundplane" texture="groundplane" texuniform="true" texrepeat="5 5" reflectance="0"/>
    <texture type="skybox" builtin="gradient" rgb1=".4 .5 .6" rgb2="0 0 0" width="100" height="100"/>
    <texture builtin="flat" height="1278" mark="cross" markrgb="1 1 1" name="texgeom" random="0.01" rgb1="0.8 0.6 0.4" rgb2="0.8 0.6 0.4" type="cube" width="127"/>
    <texture name="texplane" builtin="checker" height="512" width="512" rgb1=".2 .3 .4" rgb2=".1 .15 .2" type="2d" />
    <material name="MatPlane" reflectance="0.5" shininess="0.01" specular="0.1" texrepeat="1 1" texture="texplane" texuniform="true" />
    <material name="geom" texture="texgeom" texuniform="true"/>
  </asset>
   <worldbody>
    <geom name="floor" size="0 0 0.01" type="plane" material="groundplane" contype="1" conaffinity="0" priority="1"
      friction="0.6" condim="3"/>

        <light diffuse=".5 .5 .5" pos="-3 -3 5" dir="3 3 -5" castshadow="true"/>

  </worldbody>
</mujoco>